Workbook
Name Segment_Maint_Rx.Technologie: #N/A

Sheet Client
A1: Source.Name | B1: ID_Client | C1: Province_Client | D1: Anciennete_Clie | E1: Anciennete_Mois | F1: Type_Forfait | G1: Duree_Cumulee_Panne | H1: Duree_Cumulee_Panne_Min | I1: Facture_Mensuelle | J1: Plaintes_Service_Client | K1: Remises | L1: Mont_Remise
A2: Clients_Churn_Part_01.xlsx | B2: CLI-01147 | C2: Ituri | D2: =INT('Client'!$E2/12) & " ans et " & MOD('Client'!$E2,12) & " mois" -> 2 ans et 5 mois | E2: 29 | F2: Premium 5G 150Go | G2: =Client[[#This Row],[Duree_Cumulee_Panne_Min]]/1440 -> 0.14861111 | H2: 214 | I2: 74.7 | J2: 3 | K2: =IF('Client'!$F2="Pro Monde",10%,IF(AND('Client'!$G2>12,'Client'!$D2>5),70%,IF(AND(OR('Client'!$G2>=4,'Client'!$G2<=12,'Client'!$D2<5,(OR('Client'!$F2="Premium ")))),45%,0%))) -> 0.45 | L2: ='Client'!$I2* ('Client'!$K2/100) -> 0.33615
A3: Clients_Churn_Part_01.xlsx | B3: CLI-00894 | C3: Tshuapa | D3: =INT('Client'!$E3/12) & " ans et " & MOD('Client'!$E3,12) & " mois" -> 5 ans et 3 mois | E3: 63 | F3: Pro Monde | G3: =Client[[#This Row],[Duree_Cumulee_Panne_Min]]/1440 -> 0.14236111 | H3: 205 | I3: 89.19 | J3: 0 | K3: =IF('Client'!$F3="Pro Monde",10%,IF(AND('Client'!$G3>12,'Client'!$D3>5),70%,IF(AND(OR('Client'!$G3>=4,'Client'!$G3<=12,'Client'!$D3<5,(OR('Client'!$F3="Premium ")))),45%,0%))) -> 0.1 | L3: ='Client'!$I3* ('Client'!$K3/100) -> 0.08919
A4: Clients_Churn_Part_01.xlsx | B4: CLI-00865 | C4: Mongala | D4: =INT('Client'!$E4/12) & " ans et " & MOD('Client'!$E4,12) & " mois" -> 2 ans et 10 mois | E4: 34 | F4: Pro Monde | G4: =Client[[#This Row],[Duree_Cumulee_Panne_Min]]/1440 -> 0.31458333 | H4: 453 | I4: 56.84 | J4: 0 | K4: =IF('Client'!$F4="Pro Monde",10%,IF(AND('Client'!$G4>12,'Client'!$D4>5),70%,IF(AND(OR('Client'!$G4>=4,'Client'!$G4<=12,'Client'!$D4<5,(OR('Client'!$F4="Premium ")))),45%,0%))) -> 0.1 | L4: ='Client'!$I4* ('Client'!$K4/100) -> 0.05684
A5: Clients_Churn_Part_01.xlsx | B5: CLI-01325 | C5: Haut-Lomami | D5: =INT('Client'!$E5/12) & " ans et " & MOD('Client'!$E5,12) & " mois" -> 3 ans et 8 mois | E5: 44 | F5: Bloqué 5Go | G5: =Client[[#This Row],[Duree_Cumulee_Panne_Min]]/1440 -> 0.24166667 | H5: 348 | I5: 58.67 | J5: 0 | K5: =IF('Client'!$F5="Pro Monde",10%,IF(AND('Client'!$G5>12,'Client'!$D5>5),70%,IF(AND(OR('Client'!$G5>=4,'Client'!$G5<=12,'Client'!$D5<5,(OR('Client'!$F5="Premium ")))),45%,0%))) -> 0.45 | L5: ='Client'!$I5* ('Client'!$K5/100) -> 0.264015
A6: Clients_Churn_Part_01.xlsx | B6: CLI-01855 | C6: Sud-Kivu | D6: =INT('Client'!$E6/12) & " ans et " & MOD('Client'!$E6,12) & " mois" -> 8 ans et 5 mois | E6: 101 | F6: Illimité 50Go | G6: =Client[[#This Row],[Duree_Cumulee_Panne_Min]]/1440 -> 0.24861111 | H6: 358 | I6: 29.24 | J6: 3 | K6: =IF('Client'!$F6="Pro Monde",10%,IF(AND('Client'!$G6>12,'Client'!$D6>5),70%,IF(AND(OR('Client'!$G6>=4,'Client'!$G6<=12,'Client'!$D6<5,(OR('Client'!$F6="Premium ")))),45%,0%))) -> 0.45 | L6: ='Client'!$I6* ('Client'!$K6/100) -> 0.13158
A7: Clients_Churn_Part_01.xlsx | B7: CLI-00076 | C7: Haut-Katanga | D7: =INT('Client'!$E7/12) & " ans et " & MOD('Client'!$E7,12) & " mois" -> 3 ans et 10 mois | E7: 46 | F7: Premium 5G 150Go | G7: =Client[[#This Row],[Duree_Cumulee_Panne_Min]]/1440 -> 0.19652778 | H7: 283 | I7: 56.05 | J7: 1 | K7: =IF('Client'!$F7="Pro Monde",10%,IF(AND('Client'!$G7>12,'Client'!$D7>5),70%,IF(AND(OR('Client'!$G7>=4,'Client'!$G7<=12,'Client'!$D7<5,(OR('Client'!$F7="Premium ")))),45%,0%))) -> 0.45 | L7: ='Client'!$I7* ('Client'!$K7/100) -> 0.252225
A8: Clients_Churn_Part_01.xlsx | B8: CLI-00414 | C8: Bas-Uele | D8: =INT('Client'!$E8/12) & " ans et " & MOD('Client'!$E8,12) & " mois" -> 8 ans et 3 mois | E8: 99 | F8: Premium 5G 150Go | G8: =Client[[#This Row],[Duree_Cumulee_Panne_Min]]/1440 -> 0.31041667 | H8: 447 | I8: 38.1 | J8: 3 | K8: =IF('Client'!$F8="Pro Monde",10%,IF(AND('Client'!$G8>12,'Client'!$D8>5),70%,IF(AND(OR('Client'!$G8>=4,'Client'!$G8<=12,'Client'!$D8<5,(OR('Client'!$F8="Premium ")))),45%,0%))) -> 0.45 | L8: ='Client'!$I8* ('Client'!$K8/100) -> 0.17145
A9: Clients_Churn_Part_01.xlsx | B9: CLI-00327 | C9: Haut-Katanga | D9: =INT('Client'!$E9/12) & " ans et " & MOD('Client'!$E9,12) & " mois" -> 0 ans et 6 mois | E9: 6 | F9: Illimité 50Go | G9: =Client[[#This Row],[Duree_Cumulee_Panne_Min]]/1440 -> 0.10763889 | H9: 155 | I9: 40.66 | J9: 1 | K9: =IF('Client'!$F9="Pro Monde",10%,IF(AND('Client'!$G9>12,'Client'!$D9>5),70%,IF(AND(OR('Client'!$G9>=4,'Client'!$G9<=12,'Client'!$D9<5,(OR('Client'!$F9="Premium ")))),45%,0%))) -> 0.45 | L9: ='Client'!$I9* ('Client'!$K9/100) -> 0.18297
A10: Clients_Churn_Part_01.xlsx | B10: CLI-00559 | C10: Kasai | D10: =INT('Client'!$E10/12) & " ans et " & MOD('Client'!$E10,12) & " mois" -> 8 ans et 3 mois | E10: 99 | F10: Bloqué 5Go | G10: =Client[[#This Row],[Duree_Cumulee_Panne_Min]]/1440 -> 0.25625 | H10: 369 | I10: 67.21 | J10: 3 | K10: =IF('Client'!$F10="Pro Monde",10%,IF(AND('Client'!$G10>12,'Client'!$D10>5),70%,IF(AND(OR('Client'!$G10>=4,'Client'!$G10<=12,'Client'!$D10<5,(OR('Client'!$F10="Premium ")))),45%,0%))) -> 0.45 | L10: ='Client'!$I10* ('Client'!$K10/100) -> 0.302445
A11: Clients_Churn_Part_01.xlsx | B11: CLI-00280 | C11: Sud-Ubangi | D11: =INT('Client'!$E11/12) & " ans et " & MOD('Client'!$E11,12) & " mois" -> 9 ans et 5 mois | E11: 113 | F11: Illimité 50Go | G11: =Client[[#This Row],[Duree_Cumulee_Panne_Min]]/1440 -> 0.26388889 | H11: 380 | I11: 12.11 | J11: 0 | K11: =IF('Client'!$F11="Pro Monde",10%,IF(AND('Client'!$G11>12,'Client'!$D11>5),70%,IF(AND(OR('Client'!$G11>=4,'Client'!$G11<=12,'Client'!$D11<5,(OR('Client'!$F11="Premium ")))),45%,0%))) -> 0.45 | L11: ='Client'!$I11* ('Client'!$K11/100) -> 0.054495
A12: Clients_Churn_Part_01.xlsx | B12: CLI-00060 | C12: Kasai-Central | D12: =INT('Client'!$E12/12) & " ans et " & MOD('Client'!$E12,12) & " mois" -> 6 ans et 0 mois | E12: 72 | F12: Pro Monde | G12: =Client[[#This Row],[Duree_Cumulee_Panne_Min]]/1440 -> 0.11111111 | H12: 160 | I12: 90.13 | J12: 2 | K12: =IF('Client'!$F12="Pro Monde",10%,IF(AND('Client'!$G12>12,'Client'!$D12>5),70%,IF(AND(OR('Client'!$G12>=4,'Client'!$G12<=12,'Client'!$D12<5,(OR('Client'!$F12="Premium ")))),45%,0%))) -> 0.1 | L12: ='Client'!$I12* ('Client'!$K12/100) -> 0.09013
A13: Clients_Churn_Part_01.xlsx | B13: CLI-00530 | C13: Sankuru | D13: =INT('Client'!$E13/12) & " ans et " & MOD('Client'!$E13,12) & " mois" -> 2 ans et 11 mois | E13: 35 | F13: Pro Monde | G13: =Client[[#This Row],[Duree_Cumulee_Panne_Min]]/1440 -> 0.32291667 | H13: 465 | I13: 58.59 | J13: 5 | K13: =IF('Client'!$F13="Pro Monde",10%,IF(AND('Client'!$G13>12,'Client'!$D13>5),70%,IF(AND(OR('Client'!$G13>=4,'Client'!$G13<=12,'Client'!$D13<5,(OR('Client'!$F13="Premium ")))),45%,0%))) -> 0.1 | L13: ='Client'!$I13* ('Client'!$K13/100) -> 0.05859
... A749: Clients_Churn_Part_15.xlsx | B749: CLI-00800 | C749: Nord-Kivu | D749: =INT('Client'!$E749/12) & " ans et " & MOD('Client'!$E749,12) & " mois" -> 0 ans et 4 mois | E749: 4 | F749: Bloqué 5Go | G749: =Client[[#This Row],[Duree_Cumulee_Panne_Min]]/1440 -> 0.014583333 | H749: 21 | I749: 45.8 | J749: 1 | K749: =IF('Client'!$F749="Pro Monde",10%,IF(AND('Client'!$G749>12,'Client'!$D749>5),70%,IF(AND(OR('Client'!$G749>=4,'Client'!$G749<=12,'Client'!$D749<5,(OR('Client'!$F749="Premium ")))),45%,0%))) -> 0.45 | L749: ='Client'!$I749* ('Client'!$K749/100) -> 0.2061

Sheet Logs_Reseau2
A1: Source.Name | B1: Date_Heure_Panne | C1: Cell_ID | D1: Duree_Panne_Min | E1: Statut_Resolution | F1: Date_Heure_Panne - Copier
A2: Logs_Reseau_Part_01.xlsx | B2: 45208 | C2: ANT-0004 | D2: 38 | E2: Résolu | F2: 0.30138889
A3: Logs_Reseau_Part_01.xlsx | B3: 45204 | C3: ANT-0977 | D3: 100 | E3: Non Résolu | F3: 0.9625
A4: Logs_Reseau_Part_01.xlsx | B4: 45221 | C4: ANT-0740 | D4: 79 | E4: En Cours | F4: 0.99791667
A5: Logs_Reseau_Part_01.xlsx | B5: 45217 | C5: ANT-0897 | D5: 59 | E5: Résolu | F5: 0.10902778
A6: Logs_Reseau_Part_01.xlsx | B6: 45213 | C6: ANT-0737 | D6: 119 | E6: Non Résolu | F6: 0.042361111
A7: Logs_Reseau_Part_01.xlsx | B7: 45202 | C7: ANT-0270 | D7: 79 | E7: Résolu | F7: 0.25972222
A8: Logs_Reseau_Part_01.xlsx | B8: 45216 | C8: ANT-0996 | D8: 56 | E8: Résolu | F8: 0.79236111
A9: Logs_Reseau_Part_01.xlsx | B9: 45217 | C9: ANT-0513 | D9: 51 | E9: Non Résolu | F9: 0.28125
A10: Logs_Reseau_Part_01.xlsx | B10: 45220 | C10: ANT-0781 | D10: 33 | E10: En Cours | F10: 0.94027778
A11: Logs_Reseau_Part_01.xlsx | B11: 45213 | C11: ANT-0183 | D11: 22 | E11: Non Résolu | F11: 0.31111111
A12: Logs_Reseau_Part_01.xlsx | B12: 45218 | C12: ANT-0520 | D12: 70 | E12: Résolu | F12: 0.36875
A13: Logs_Reseau_Part_01.xlsx | B13: 45225 | C13: ANT-0109 | D13: 16 | E13: Non Résolu | F13: 0.23888889
... A1034: Logs_Reseau_Part_25.xlsx | B1034: 45229 | C1034: ANT-0635 | D1034: 37 | E1034: En Cours | F1034: 0.98680556

Sheet Maintenance_Rx
A1: Source.Name | B1: ID_Antenne | C1: Province_RDC | D1: Latitude | E1: Longitude | F1: Technologie | G1: Equipementier
A2: Registre_Maintenance_Part_01.xlsx | B2: ANT-0622 | C2: Haut-Uele | D2: -3.003879 | E2: 23.633893 | F2: 5G | G2: Ericsson
A3: Registre_Maintenance_Part_01.xlsx | B3: ANT-0084 | C3: Kwilu | D3: 2.413557 | E3: 19.690682 | F3: 4G | G3: Huawei
A4: Registre_Maintenance_Part_01.xlsx | B4: ANT-0862 | C4: Tanganyika | D4: -9.470862 | E4: 29.234388 | F4: 3G | G4: ZTE
A5: Registre_Maintenance_Part_01.xlsx | B5: ANT-0288 | C5: Tshopo | D5: 1.400674 | E5: 13.503127 | F5: 5G | G5: ZTE
A6: Registre_Maintenance_Part_01.xlsx | B6: ANT-0880 | C6: Haut-Uele | D6: 0.293756 | E6: 18.528884 | F6: 5G | G6: ZTE
A7: Registre_Maintenance_Part_01.xlsx | B7: ANT-0847 | C7: Maniema | D7: -4.486234 | E7: 17.956159 | F7: 3G | G7: Huawei
A8: Registre_Maintenance_Part_01.xlsx | B8: ANT-0144 | C8: Tanganyika | D8: -12.824639 | E8: 24.407249 | F8: 5G | G8: Huawei
A9: Registre_Maintenance_Part_01.xlsx | B9: ANT-0913 | C9: Kinshasa | D9: -5.412628 | E9: 25.498236 | F9: 5G | G9: ZTE
A10: Registre_Maintenance_Part_01.xlsx | B10: ANT-0552 | C10: Kinshasa | D10: -10.57951 | E10: 23.502314 | F10: 4G | G10: ZTE
A11: Registre_Maintenance_Part_01.xlsx | B11: ANT-0202 | C11: Tshuapa | D11: 3.078867 | E11: 19.513651 | F11: 5G | G11: Huawei
A12: Registre_Maintenance_Part_01.xlsx | B12: ANT-0270 | C12: Kasai-Central | D12: -1.648264 | E12: 28.866144 | F12: 5G | G12: Ericsson
A13: Registre_Maintenance_Part_01.xlsx | B13: ANT-0752 | C13: Nord-Kivu | D13: -3.388313 | E13: 26.838507 | F13: 5G | G13: Nokia
... A499: Registre_Maintenance_Part_10.xlsx | B499: ANT-0090 | C499: Kasai-Central | D499: -7.337934 | E499: 28.404002 | F499: 3G | G499: Nokia

Sheet Vlookup
A1: Source.Name | B1: Date_Heure_Panne | C1: Date_Heure_Panne - Copier | D1: Cell_ID | E1: Duree_Panne_Min | F1: Statut_Resolution | G1: Maintenance_Rx.ID_Antenne | H1: Maintenance_Rx.Province_RDC | I1: Maintenance_Rx.Latitude | J1: Maintenance_Rx.Longitude | K1: Maintenance_Rx.Technologie | L1: Maintenance_Rx.Equipementier
A2: Logs_Reseau_Part_01.xlsx | B2: 45212 | C2: 0.14027778 | D2: ANT-0862 | E2: 19 | F2: Non Résolu | G2: ANT-0862 | H2: Tanganyika | I2: -9.470862 | J2: 29.234388 | K2: 3G | L2: ZTE
A3: Logs_Reseau_Part_01.xlsx | B3: 45213 | C3: 0.042361111 | D3: ANT-0737 | E3: 119 | F3: Non Résolu | G3: ANT-0737 | H3: Kongo-Central | I3: -2.821152 | J3: 20.651419 | K3: 5G | L3: Ericsson
A4: Logs_Reseau_Part_01.xlsx | B4: 45202 | C4: 0.25972222 | D4: ANT-0270 | E4: 79 | F4: Résolu | G4: ANT-0270 | H4: Kasai-Central | I4: -1.648264 | J4: 28.866144 | K4: 5G | L4: Ericsson
A5: Logs_Reseau_Part_03.xlsx | B5: 45210 | C5: 0.56805556 | D5: ANT-0913 | E5: 96 | F5: Résolu | G5: ANT-0913 | H5: Kinshasa | I5: -5.412628 | J5: 25.498236 | K5: 5G | L5: ZTE
A6: Logs_Reseau_Part_01.xlsx | B6: 45213 | C6: 0.31111111 | D6: ANT-0183 | E6: 22 | F6: Non Résolu | G6: ANT-0183 | H6: Kwango | I6: 4.831904 | J6: 20.733469 | K6: 5G | L6: Ericsson
A7: Logs_Reseau_Part_01.xlsx | B7: 45218 | C7: 0.36875 | D7: ANT-0520 | E7: 70 | F7: Résolu | G7: ANT-0520 | H7: Lomami | I7: -8.422786 | J7: 16.781293 | K7: 4G | L7: Huawei
A8: Logs_Reseau_Part_01.xlsx | B8: 45208 | C8: 0.073611111 | D8: ANT-0520 | E8: 85 | F8: Non Résolu | G8: ANT-0520 | H8: Lomami | I8: -8.422786 | J8: 16.781293 | K8: 4G | L8: Huawei
A9: Logs_Reseau_Part_01.xlsx | B9: 45204 | C9: 0.28333333 | D9: ANT-0641 | E9: 11 | F9: En Cours | G9: ANT-0641 | H9: Lomami | I9: -2.237157 | J9: 25.926188 | K9: 3G | L9: Nokia
A10: Logs_Reseau_Part_05.xlsx | B10: 45215 | C10: 0.37638889 | D10: ANT-0641 | E10: 65 | F10: En Cours | G10: ANT-0641 | H10: Lomami | I10: -2.237157 | J10: 25.926188 | K10: 3G | L10: Nokia
A11: Logs_Reseau_Part_03.xlsx | B11: 45216 | C11: 0.90277778 | D11: ANT-0642 | E11: 20 | F11: En Cours | G11: ANT-0642 | H11: Kwilu | I11: -4.240836 | J11: 26.210014 | K11: 4G | L11: Huawei
A12: Logs_Reseau_Part_08.xlsx | B12: 45221 | C12: 0.37638889 | D12: ANT-0079 | E12: 59 | F12: En Cours | G12: ANT-0079 | H12: Maniema | I12: -8.482467 | J12: 21.897778 | K12: 5G | L12: Ericsson
A13: Logs_Reseau_Part_02.xlsx | B13: 45216 | C13: 0.67361111 | D13: ANT-0078 | E13: 117 | F13: Résolu | G13: ANT-0078 | H13: Sud-Ubangi | I13: -12.141233 | J13: 15.179044 | K13: 5G | L13: Ericsson
... A524: Logs_Reseau_Part_25.xlsx | B524: 45209 | C524: 0.91388889 | D524: ANT-0292 | E524: 111 | F524: En Cours | G524: ANT-0292 | H524: Bas-Uele | I524: -6.419719 | J524: 22.287264 | K524: 3G | L524: Ericsson

Sheet TCD
B3: Étiquettes de colonnes
B4: 3G | E4: 4G | H4: 5G | K4: Total Nombre de Client.ID_Client | L4: Total Somme de Duree_Cumulee_Panne | M4: Total Somme de Montant_Remise
A5: Étiquettes de lignes | B5: Nombre de Client.ID_Client | C5: Somme de Duree_Cumulee_Panne | D5: Somme de Montant_Remise | E5: Nombre de Client.ID_Client | F5: Somme de Duree_Cumulee_Panne | G5: Somme de Montant_Remise | H5: Nombre de Client.ID_Client | I5: Somme de Duree_Cumulee_Panne | J5: Somme de Montant_Remise
A6: Bas-Uele | B6: 32 | C6: 6.3319444 | D6: 6.108 | K6: 32 | L6: 6.3319444 | M6: 6.108
A7: Bloqué 5Go | B7: 8 | C7: 1.5048611 | D7: 2.184 | K7: 8 | L7: 1.5048611 | M7: 2.184
A8: Illimité 50Go | B8: 6 | C8: 1.0208333 | D8: 1.062 | K8: 6 | L8: 1.0208333 | M8: 1.062
A9: Premium 5G 150Go | B9: 8 | C9: 1.7131944 | D9: 2.216 | K9: 8 | L9: 1.7131944 | M9: 2.216
A10: Pro Monde | B10: 10 | C10: 2.0930556 | D10: 0.646 | K10: 10 | L10: 2.0930556 | M10: 0.646
A11: Equateur | E11: 24 | F11: 4.2861111 | G11: 4.5 | K11: 24 | L11: 4.2861111 | M11: 4.5
A12: Bloqué 5Go | E12: 3 | F12: 0.74652778 | G12: 0.782 | K12: 3 | L12: 0.74652778 | M12: 0.782
A13: Illimité 50Go | E13: 8 | F13: 1.4881944 | G13: 1.533 | K13: 8 | L13: 1.4881944 | M13: 1.533
A14: Premium 5G 150Go | E14: 7 | F14: 1.3347222 | G14: 1.748 | K14: 7 | L14: 1.3347222 | M14: 1.748
A15: Pro Monde | E15: 6 | F15: 0.71666667 | G15: 0.437 | K15: 6 | L15: 0.71666667 | M15: 0.437
A16: Haut-Katanga | B16: 38 | C16: 7.0847222 | D16: 6.809 | K16: 38 | L16: 7.0847222 | M16: 6.809
A17: Bloqué 5Go | B17: 10 | C17: 2.1090278 | D17: 2.904 | K17: 10 | L17: 2.1090278 | M17: 2.904
A18: Illimité 50Go | B18: 8 | C18: 1.1138889 | D18: 1.821 | K18: 8 | L18: 1.1138889 | M18: 1.821
A19: Premium 5G 150Go | B19: 9 | C19: 1.7986111 | D19: 1.506 | K19: 9 | L19: 1.7986111 | M19: 1.506
A20: Pro Monde | B20: 11 | C20: 2.0631944 | D20: 0.578 | K20: 11 | L20: 2.0631944 | M20: 0.578
A21: Haut-Lomami | E21: 33 | F21: 6.4895833 | G21: 5.615 | K21: 33 | L21: 6.4895833 | M21: 5.615
A22: Bloqué 5Go | E22: 12 | F22: 2.1875 | G22: 2.2 | K22: 12 | L22: 2.1875 | M22: 2.2
A23: Illimité 50Go | E23: 6 | F23: 0.90555556 | G23: 2.016 | K23: 6 | L23: 0.90555556 | M23: 2.016
A24: Premium 5G 150Go | E24: 7 | F24: 1.9270833 | G24: 1.038 | K24: 7 | L24: 1.9270833 | M24: 1.038
A25: Pro Monde | E25: 8 | F25: 1.4694444 | G25: 0.361 | K25: 8 | L25: 1.4694444 | M25: 0.361
A26: Haut-Uele | E26: 15 | F26: 2.6465278 | G26: 2.732 | K26: 15 | L26: 2.6465278 | M26: 2.732
A27: Bloqué 5Go | E27: 1 | F27: 0.32083333 | G27: 0.082 | K27: 1 | L27: 0.32083333 | M27: 0.082
A28: Illimité 50Go | E28: 3 | F28: 0.43402778 | G28: 0.647 | K28: 3 | L28: 0.43402778 | M28: 0.647
A29: Premium 5G 150Go | E29: 7 | F29: 1.3729167 | G29: 1.757 | K29: 7 | L29: 1.3729167 | M29: 1.757
A30: Pro Monde | E30: 4 | F30: 0.51875 | G30: 0.246 | K30: 4 | L30: 0.51875 | M30: 0.246
A31: Ituri | B31: 37 | C31: 6.2458333 | D31: 8.634 | K31: 37 | L31: 6.2458333 | M31: 8.634
A32: Bloqué 5Go | B32: 10 | C32: 1.7180556 | D32: 2.812 | K32: 10 | L32: 1.7180556 | M32: 2.812
A33: Illimité 50Go | B33: 9 | C33: 1.2958333 | D33: 2.438 | K33: 9 | L33: 1.2958333 | M33: 2.438
A34: Premium 5G 150Go | B34: 12 | C34: 2.19375 | D34: 3.074 | K34: 12 | L34: 2.19375 | M34: 3.074
A35: Pro Monde | B35: 6 | C35: 1.0381944 | D35: 0.31 | K35: 6 | L35: 1.0381944 | M35: 0.31
A36: Kasai | E36: 27 | F36: 4.8013889 | G36: 6.049 | K36: 27 | L36: 4.8013889 | M36: 6.049
A37: Bloqué 5Go | E37: 8 | F37: 1.5076389 | G37: 2.57 | K37: 8 | L37: 1.5076389 | M37: 2.57
A38: Illimité 50Go | E38: 7 | F38: 1.1083333 | G38: 1.512 | K38: 7 | L38: 1.1083333 | M38: 1.512
A39: Premium 5G 150Go | E39: 7 | F39: 1.2333333 | G39: 1.673 | K39: 7 | L39: 1.2333333 | M39: 1.673
A40: Pro Monde | E40: 5 | F40: 0.95208333 | G40: 0.294 | K40: 5 | L40: 0.95208333 | M40: 0.294
A41: Kasai-Central | H41: 27 | I41: 4.9868056 | J41: 4.353 | K41: 27 | L41: 4.9868056 | M41: 4.353
A42: Bloqué 5Go | H42: 6 | I42: 0.76805556 | J42: 1.942 | K42: 6 | L42: 0.76805556 | M42: 1.942
...

Sheet Matrice2
A1: Source.Name | B1: Date_Panne | C1: Heure_Panne - Copier | D1: Cell_ID | E1: Duree_Panne_Min | F1: Statut_Resolution | G1: Maint_Rx.ID_Antenne | H1: Maint_Rx.Province_RDC | I1: Maintenance_Rx.Latitude | J1: Maintenance_Rx.Longitude | K1: Maint_Rx.Technologie | L1: Maint_Rx.Equipementier | M1: Client.ID_Client | N1: Client.Province_Client | O1: Anciennete_Mois | P1: Client.Anciennete_Mois2 | Q1: Client.Type_Forfait | R1: Duree_Cumulee_Panne | S1: Client.Duree_Cumulee_Panne_Min | T1: Client.Facture_Mensuelle | U1: Client.Plaintes_Service_Client | V1: Remise | W1: Montant_Remise
A2: Logs_Reseau_Part_01.xlsx | B2: 45212 | C2: 0.14027778 | D2: ANT-0862 | E2: 19 | F2: Non Résolu | G2: ANT-0862 | H2: Tanganyika | I2: -9.470862 | J2: 29.234388 | K2: 3G | L2: ZTE | M2: CLI-01618 | N2: Tanganyika | O2: 9 ans et 7 mois | P2: 115 | Q2: Bloqué 5Go | R2: 0.12222222 | S2: 176 | T2: 33.28 | U2: 4 | V2: 0.45 | W2: 0.15
A3: Logs_Reseau_Part_01.xlsx | B3: 45212 | C3: 0.14027778 | D3: ANT-0862 | E3: 19 | F3: Non Résolu | G3: ANT-0862 | H3: Tanganyika | I3: -9.470862 | J3: 29.234388 | K3: 3G | L3: ZTE | M3: CLI-00232 | N3: Tanganyika | O3: 5 ans et 9 mois | P3: 69 | Q3: Bloqué 5Go | R3: 0.2125 | S3: 306 | T3: 13.97 | U3: 1 | V3: 0.45 | W3: 0.063
A4: Logs_Reseau_Part_01.xlsx | B4: 45212 | C4: 0.14027778 | D4: ANT-0862 | E4: 19 | F4: Non Résolu | G4: ANT-0862 | H4: Tanganyika | I4: -9.470862 | J4: 29.234388 | K4: 3G | L4: ZTE | M4: CLI-01802 | N4: Tanganyika | O4: 4 ans et 7 mois | P4: 55 | Q4: Bloqué 5Go | R4: 0.28263889 | S4: 407 | T4: 23.11 | U4: 0 | V4: 0.45 | W4: 0.104
A5: Logs_Reseau_Part_01.xlsx | B5: 45212 | C5: 0.14027778 | D5: ANT-0862 | E5: 19 | F5: Non Résolu | G5: ANT-0862 | H5: Tanganyika | I5: -9.470862 | J5: 29.234388 | K5: 3G | L5: ZTE | M5: CLI-01607 | N5: Tanganyika | O5: 6 ans et 11 mois | P5: 83 | Q5: Pro Monde | R5: 0.15208333 | S5: 219 | T5: 52.26 | U5: 1 | V5: 0.1 | W5: 0.052
A6: Logs_Reseau_Part_01.xlsx | B6: 45212 | C6: 0.14027778 | D6: ANT-0862 | E6: 19 | F6: Non Résolu | G6: ANT-0862 | H6: Tanganyika | I6: -9.470862 | J6: 29.234388 | K6: 3G | L6: ZTE | M6: CLI-00017 | N6: Tanganyika | O6: 2 ans et 5 mois | P6: 29 | Q6: Illimité 50Go | R6: 0.086111111 | S6: 124 | T6: 43.83 | U6: 5 | V6: 0.45 | W6: 0.197
A7: Logs_Reseau_Part_01.xlsx | B7: 45212 | C7: 0.14027778 | D7: ANT-0862 | E7: 19 | F7: Non Résolu | G7: ANT-0862 | H7: Tanganyika | I7: -9.470862 | J7: 29.234388 | K7: 3G | L7: ZTE | M7: CLI-00617 | N7: Tanganyika | O7: 6 ans et 11 mois | P7: 83 | Q7: Pro Monde | R7: 0.29166667 | S7: 420 | T7: 94.9 | U7: 1 | V7: 0.1 | W7: 0.095
A8: Logs_Reseau_Part_01.xlsx | B8: 45212 | C8: 0.14027778 | D8: ANT-0862 | E8: 19 | F8: Non Résolu | G8: ANT-0862 | H8: Tanganyika | I8: -9.470862 | J8: 29.234388 | K8: 3G | L8: ZTE | M8: CLI-00899 | N8: Tanganyika | O8: 4 ans et 0 mois | P8: 48 | Q8: Pro Monde | R8: 0.052777778 | S8: 76 | T8: 39.35 | U8: 2 | V8: 0.1 | W8: 0.039
A9: Logs_Reseau_Part_01.xlsx | B9: 45212 | C9: 0.14027778 | D9: ANT-0862 | E9: 19 | F9: Non Résolu | G9: ANT-0862 | H9: Tanganyika | I9: -9.470862 | J9: 29.234388 | K9: 3G | L9: ZTE | M9: CLI-00007 | N9: Tanganyika | O9: 9 ans et 2 mois | P9: 110 | Q9: Bloqué 5Go | R9: 0.077777778 | S9: 112 | T9: 98.95 | U9: 5 | V9: 0.45 | W9: 0.445
A10: Logs_Reseau_Part_01.xlsx | B10: 45212 | C10: 0.14027778 | D10: ANT-0862 | E10: 19 | F10: Non Résolu | G10: ANT-0862 | H10: Tanganyika | I10: -9.470862 | J10: 29.234388 | K10: 3G | L10: ZTE | M10: CLI-00626 | N10: Tanganyika | O10: 0 ans et 2 mois | P10: 2 | Q10: Pro Monde | R10: 0.098611111 | S10: 142 | T10: 37.8 | U10: 0 | V10: 0.1 | W10: 0.038
A11: Logs_Reseau_Part_01.xlsx | B11: 45212 | C11: 0.14027778 | D11: ANT-0862 | E11: 19 | F11: Non Résolu | G11: ANT-0862 | H11: Tanganyika | I11: -9.470862 | J11: 29.234388 | K11: 3G | L11: ZTE | M11: CLI-01702 | N11: Tanganyika | O11: 5 ans et 3 mois | P11: 63 | Q11: Bloqué 5Go | R11: 0.27222222 | S11: 392 | T11: 93.11 | U11: 3 | V11: 0.45 | W11: 0.419
A12: Logs_Reseau_Part_01.xlsx | B12: 45212 | C12: 0.14027778 | D12: ANT-0862 | E12: 19 | F12: Non Résolu | G12: ANT-0862 | H12: Tanganyika | I12: -9.470862 | J12: 29.234388 | K12: 3G | L12: ZTE | M12: CLI-00241 | N12: Tanganyika | O12: 4 ans et 2 mois | P12: 50 | Q12: Bloqué 5Go | R12: 0.17222222 | S12: 248 | T12: 69.42 | U12: 0 | V12: 0.45 | W12: 0.312
A13: Logs_Reseau_Part_01.xlsx | B13: 45212 | C13: 0.14027778 | D13: ANT-0862 | E13: 19 | F13: Non Résolu | G13: ANT-0862 | H13: Tanganyika | I13: -9.470862 | J13: 29.234388 | K13: 3G | L13: ZTE | M13: CLI-01706 | N13: Tanganyika | O13: 4 ans et 7 mois | P13: 55 | Q13: Premium 5G 150Go | R13: 0.059722222 | S13: 86 | T13: 17.44 | U13: 2 | V13: 0.45 | W13: 0.078
... A749: Logs_Reseau_Part_01.xlsx | B749: 45201 | C749: 0.88472222 | D749: ANT-0553 | E749: 54 | F749: En Cours | G749: ANT-0553 | H749: Nord-Kivu | I749: 4.628716 | J749: 19.407078 | K749: 4G | L749: Ericsson | M749: CLI-00800 | N749: Nord-Kivu | O749: 0 ans et 4 mois | P749: 4 | Q749: Bloqué 5Go | R749: 0.014583333 | S749: 21 | T749: 45.8 | U749: 1 | V749: 0.45 | W749: 0.206
